Workbook

Sheet test_output
A1: startphrase | B1: ending1 | C1: ending2 | D1: labels | E1: xid | F1: simile type | G1: met sim | H1: paired sim neg pair type | I1: negation | K1: Llama-3-70B-Instruct M1 1 | L1: Llama-3-70B-Instruct M1 2 | M1: Llama-3-70B-Instruct M1 bin | N1: Llama-3-70B-Instruct M2 1 | O1: Llama-3-70B-Instruct M2 2 | P1: Llama-3-70B-Instruct M2 bin | Q1: Llama-3-70B-Instruct M3 1 | R1: Llama-3-70B-Instruct M3 2 | S1: Llama-3-70B-Instruct M3 bin | T1: Llama-3-70B-Instruct M4 1 | U1: Llama-3-70B-Instruct M4 2 | V1: Llama-3-70B-Instruct M4 bin | W1: Llama-3-70B-Instruct M5 1 | X1: Llama-3-70B-Instruct M5 2 | Y1: Llama-3-70B-Instruct M5 bin | Z1: Llama-3.1-70B-Instruct M1 1 | AA1: Llama-3.1-70B-Instruct M1 2 | AB1: Llama-3.1-70B-Instruct M1 bin | AC1: Llama-3.1-70B-Instruct M2 1 | AD1: Llama-3.1-70B-Instruct M2 2 | AE1: Llama-3.1-70B-Instruct M2 bin | AF1: Llama-3.1-70B-Instruct M3 1 | AG1: Llama-3.1-70B-Instruct M3 2 | AH1: Llama-3.1-70B-Instruct M3 bin | AI1: Llama-3.1-70B-Instruct M4 1 | AJ1: Llama-3.1-70B-Instruct M4 2 | AK1: Llama-3.1-70B-Instruct M4 bin | AL1: Llama-3.1-70B-Instruct M5 1 | AM1: Llama-3.1-70B-Instruct M5 2 | AN1: Llama-3.1-70B-Instruct M5 bin | AO1: Llama-3.1-405B-Instruct M1 1 | AP1: Llama-3.1-405B-Instruct M1 2 | AQ1: Llama-3.1-405B-Instruct M1 bin | AR1: Llama-3.1-405B-Instruct M2 1 | AS1: Llama-3.1-405B-Instruct M2 2 | AT1: Llama-3.1-405B-Instruct M2 bin | AU1: Llama-3.1-405B-Instruct M3 1 | AV1: Llama-3.1-405B-Instruct M3 2 | AW1: Llama-3.1-405B-Instruct M3 bin | AX1: Llama-3.1-405B-Instruct M4 1 | AY1: Llama-3.1-405B-Instruct M4 2 | AZ1: Llama-3.1-405B-Instruct M4 bin | BA1: Llama-3.1-405B-Instruct M5 1 | BB1: Llama-3.1-405B-Instruct M5 2 | BC1: Llama-3.1-405B-Instruct M5 bin | BD1: Llama-3.3-70B-Instruct M1 1 | BE1: Llama-3.3-70B-Instruct M1 2 | BF1: Llama-3.3-70B-Instruct M1 bin | BG1: Llama-3.3-70B-Instruct M2 1 | BH1: Llama-3.3-70B-Instruct M2 2 | BI1: Llama-3.3-70B-Instruct M2 bin | BJ1: Llama-3.3-70B-Instruct M3 1 | BK1: Llama-3.3-70B-Instruct M3 2 | BL1: Llama-3.3-70B-Instruct M3 bin | BM1: Llama-3.3-70B-Instruct M4 1 | BN1: Llama-3.3-70B-Instruct M4 2 | BO1: Llama-3.3-70B-Instruct M4 bin | BP1: Llama-3.3-70B-Instruct M5 1 | BQ1: Llama-3.3-70B-Instruct M5 2 | BR1: Llama-3.3-70B-Instruct M5 bin
A2: She is honest | B2: She can be trusted | C2: She can not be trusted | D2: 0 | E2: 10_0 | F2: =INDEX([1]train_xl!$H:$H,MATCH(E2,[1]train_xl!$G:$G,0)) -> the-of | G2: =INDEX([1]train_xl!$I:$I,MATCH(E2,[1]train_xl!$G:$G,0)) -> sim | H2: =INDEX([1]train_xl!$V:$V,MATCH(E2,[1]train_xl!$G:$G,0)) -> not | I2: =INDEX([2]Sheet1!$L:$L,MATCH(E2,[2]Sheet1!$I:$I,0)) -> intens | K2: -3.0821192 | L2: -3.432278 | M2: 1 | N2: -3.160059 | O2: -3.4388489 | P2: 1 | Q2: -4.1101872 | R2: -4.3781164 | S2: 1 | T2: -3.5295825 | U2: -3.9740521 | V2: 1 | W2: -4.1221828 | X2: -4.2611167 | Y2: 1 | Z2: -3.675411 | AA2: -3.8874877 | AB2: 1 | AC2: -3.623788 | AD2: -3.8212372 | AE2: 1 | AF2: -4.5752232 | AG2: -4.6816209 | AH2: 1 | AI2: -4.5686438 | AJ2: -4.7502026 | AK2: 1 | AL2: -4.2395308 | AM2: -4.3585637 | AN2: 1 | AO2: -6.4224962 | AP2: -6.4344188 | AQ2: 1 | AR2: -6.3167161 | AS2: -6.476163 | AT2: 1 | AU2: -7.4661695 | AV2: -7.552701 | AW2: 1 | AX2: -8.8796879 | AY2: -8.8296645 | AZ2: 0 | BA2: -8.7747016 | BB2: -8.6089125 | BC2: 0 | BD2: -3.7496723 | BE2: -3.9788896 | BF2: 1 | BG2: -3.7151522 | BH2: -3.9657059 | BI2: 1 | BJ2: -4.5155695 | BK2: -4.6774207 | BL2: 1 | BM2: -4.7154324 | BN2: -4.9301514 | BO2: 1 | BP2: -4.8507528 | BQ2: -4.9773968 | BR2: 1
A3: she is dishonest | B3: She can be trusted | C3: She can not be trusted | D3: 1 | E3: 10_1 | F3: =INDEX([1]train_xl!$H:$H,MATCH(E3,[1]train_xl!$G:$G,0)) -> the-of | G3: =INDEX([1]train_xl!$I:$I,MATCH(E3,[1]train_xl!$G:$G,0)) -> sim | H3: =INDEX([1]train_xl!$V:$V,MATCH(E3,[1]train_xl!$G:$G,0)) -> not | I3: =INDEX([2]Sheet1!$L:$L,MATCH(E3,[2]Sheet1!$I:$I,0)) -> neg | K3: -3.494083 | L3: -3.146713 | M3: 1 | N3: -3.3989938 | O3: -3.033006 | P3: 1 | Q3: -4.3449543 | R3: -3.9750567 | S3: 1 | T3: -4.0787208 | U3: -3.2823163 | V3: 1 | W3: -4.2224485 | X3: -3.906667 | Y3: 1 | Z3: -3.6576477 | AA3: -3.2303592 | AB3: 1 | AC3: -3.6170262 | AD3: -3.2979816 | AE3: 1 | AF3: -4.5688633 | AG3: -4.1653385 | AH3: 1 | AI3: -4.5567243 | AJ3: -3.8499041 | AK3: 1 | AL3: -4.6824617 | AM3: -4.2730043 | AN3: 1 | AO3: -6.9411218 | AP3: -6.2725945 | AQ3: 1 | AR3: -6.8095476 | AS3: -6.1001041 | AT3: 1 | AU3: -7.9857606 | AV3: -7.24481 | AW3: 1 | AX3: -9.4563176 | AY3: -8.12226 | AZ3: 1 | BA3: -10.261082 | BB3: -8.883909 | BC3: 1 | BD3: -3.6910516 | BE3: -3.3332408 | BF3: 1 | BG3: -3.6968806 | BH3: -3.3371853 | BI3: 1 | BJ3: -4.5655723 | BK3: -4.2431356 | BL3: 1 | BM3: -4.6393826 | BN3: -3.9516197 | BO3: 1 | BP3: -5.0630916 | BQ3: -4.554326 | BR3: 1
A4: The student was cooperative | B4: He was helpful | C4: he was not helpful | D4: 0 | E4: 40_0 | F4: =INDEX([1]train_xl!$H:$H,MATCH(E4,[1]train_xl!$G:$G,0)) -> as-as | G4: =INDEX([1]train_xl!$I:$I,MATCH(E4,[1]train_xl!$G:$G,0)) -> sim | H4: =INDEX([1]train_xl!$V:$V,MATCH(E4,[1]train_xl!$G:$G,0)) -> not | I4: =INDEX([2]Sheet1!$L:$L,MATCH(E4,[2]Sheet1!$I:$I,0)) -> intens | K4: -4.0762748 | L4: -3.9008533 | M4: 0 | N4: -4.337302 | O4: -4.2449836 | P4: 0 | Q4: -5.3534602 | R4: -5.1964029 | S4: 0 | T4: -5.3729881 | U4: -5.3508816 | V4: 0 | W4: -6.2122311 | X4: -5.7895555 | Y4: 0 | Z4: -4.385609 | AA4: -4.317461 | AB4: 0 | AC4: -4.6030233 | AD4: -4.5773398 | AE4: 0 | AF4: -5.8542068 | AG4: -5.6757782 | AH4: 0 | AI4: -6.1522127 | AJ4: -5.9373801 | AK4: 0 | AL4: -6.5816324 | AM4: -6.1049639 | AN4: 0 | AO4: -3.9300664 | AP4: -3.9795401 | AQ4: 1 | AR4: -3.8594745 | AS4: -4.0770779 | AT4: 1 | AU4: -4.8545769 | AV4: -4.9171673 | AW4: 1 | AX4: -4.8180686 | AY4: -5.1065844 | AZ4: 1 | BA4: -5.692257 | BB4: -5.51182 | BC4: 0 | BD4: -4.4069178 | BE4: -4.2507148 | BF4: 0 | BG4: -4.5128548 | BH4: -4.4932705 | BI4: 0 | BJ4: -5.5664235 | BK4: -5.6094276 | BL4: 1 | BM4: -6.0530984 | BN4: -5.7947902 | BO4: 0 | BP4: -6.4215988 | BQ4: -6.2489864 | BR4: 0
A5: The student was uncooperative | B5: He was helpful | C5: he was not helpful | D5: 1 | E5: 40_1 | F5: =INDEX([1]train_xl!$H:$H,MATCH(E5,[1]train_xl!$G:$G,0)) -> as-as | G5: =INDEX([1]train_xl!$I:$I,MATCH(E5,[1]train_xl!$G:$G,0)) -> sim | H5: =INDEX([1]train_xl!$V:$V,MATCH(E5,[1]train_xl!$G:$G,0)) -> not | I5: =INDEX([2]Sheet1!$L:$L,MATCH(E5,[2]Sheet1!$I:$I,0)) -> neg | K5: -3.6919081 | L5: -3.1422129 | M5: 1 | N5: -3.912942 | O5: -3.2705584 | P5: 1 | Q5: -4.6336857 | R5: -3.9868385 | S5: 1 | T5: -4.7896417 | U5: -4.0223584 | V5: 1 | W5: -4.866041 | X5: -4.341951 | Y5: 1 | Z5: -3.9754279 | AA5: -3.4367841 | AB5: 1 | AC5: -4.026218 | AD5: -3.5844309 | AE5: 1 | AF5: -4.9406883 | AG5: -4.4120227 | AH5: 1 | AI5: -5.2203571 | AJ5: -4.4748257 | AK5: 1 | AL5: -5.3093705 | AM5: -4.7578127 | AN5: 1 | AO5: -3.3999954 | AP5: -3.0158695 | AQ5: 1 | AR5: -3.4748954 | AS5: -2.9794736 | AT5: 1 | AU5: -4.0829993 | AV5: -3.6218947 | AW5: 1 | AX5: -4.3677337 | AY5: -3.7279775 | AZ5: 1 | BA5: -4.4714452 | BB5: -4.0186922 | BC5: 1 | BD5: -3.9092594 | BE5: -3.4633718 | BF5: 1 | BG5: -4.0637791 | BH5: -3.5089924 | BI5: 1 | BJ5: -4.8388801 | BK5: -4.412087 | BL5: 1 | BM5: -5.2622235 | BN5: -4.520389 | BO5: 1 | BP5: -5.4541716 | BQ5: -4.8466174 | BR5: 1
A6: The man was stylish | B6: The man was cool | C6: The man was not cool | D6: 0 | E6: 50_0 | F6: =INDEX([1]train_xl!$H:$H,MATCH(E6,[1]train_xl!$G:$G,0)) -> as-as | G6: =INDEX([1]train_xl!$I:$I,MATCH(E6,[1]train_xl!$G:$G,0)) -> sim | H6: =INDEX([1]train_xl!$V:$V,MATCH(E6,[1]train_xl!$G:$G,0)) -> not | I6: =INDEX([2]Sheet1!$L:$L,MATCH(E6,[2]Sheet1!$I:$I,0)) -> intens | K6: -4.3762359 | L6: -4.5849982 | M6: 1 | N6: -4.5229998 | O6: -4.7140233 | P6: 1 | Q6: -5.4907469 | R6: -5.6030291 | S6: 1 | T6: -5.3593964 | U6: -5.8234519 | V6: 1 | W6: -6.3341276 | X6: -6.1512358 | Y6: 0 | Z6: -5.0369053 | AA6: -5.1492638 | AB6: 1 | AC6: -5.4225944 | AD6: -5.4793989 | AE6: 1 | AF6: -6.2855329 | AG6: -6.2669097 | AH6: 0 | AI6: -6.4951697 | AJ6: -6.8210127 | AK6: 1 | AL6: -7.188299 | AM6: -6.9189821 | AN6: 0 | AO6: -3.6099995 | AP6: -3.8141121 | AQ6: 1 | AR6: -3.8404279 | AS6: -4.0261438 | AT6: 1 | AU6: -4.5758332 | AV6: -4.7189901 | AW6: 1 | AX6: -4.2520198 | AY6: -4.9080745 | AZ6: 1 | BA6: -4.9068951 | BB6: -4.9498493 | BC6: 1 | BD6: -5.4534763 | BE6: -5.5351982 | BF6: 1 | BG6: -5.6712782 | BH6: -5.7397096 | BI6: 1 | BJ6: -6.3459469 | BK6: -6.5704024 | BL6: 1 | BM6: -6.9256591 | BN6: -7.2080741 | BO6: 1 | BP6: -7.7173493 | BQ6: -7.3897066 | BR6: 0
A7: The man was unfashionable | B7: The man was cool | C7: The man was not cool | D7: 1 | E7: 50_1 | F7: =INDEX([1]train_xl!$H:$H,MATCH(E7,[1]train_xl!$G:$G,0)) -> as-as | G7: =INDEX([1]train_xl!$I:$I,MATCH(E7,[1]train_xl!$G:$G,0)) -> sim | H7: =INDEX([1]train_xl!$V:$V,MATCH(E7,[1]train_xl!$G:$G,0)) -> not | I7: =INDEX([2]Sheet1!$L:$L,MATCH(E7,[2]Sheet1!$I:$I,0)) -> neg | K7: -4.2662798 | L7: -4.0360923 | M7: 1 | N7: -4.377039 | O7: -4.0671615 | P7: 1 | Q7: -5.1506901 | R7: -4.7177338 | S7: 1 | T7: -5.2226326 | U7: -4.696588 | V7: 1 | W7: -5.6554409 | X7: -5.3055867 | Y7: 1 | Z7: -5.1289855 | AA7: -5.1820937 | AB7: 0 | AC7: -5.6854552 | AD7: -5.2908008 | AE7: 1 | AF7: -6.3019619 | AG7: -5.8392892 | AH7: 1 | AI7: -6.9757581 | AJ7: -6.3865679 | AK7: 1 | AL7: -6.8309458 | AM7: -6.3803317 | AN7: 1 | AO7: -3.6698038 | AP7: -3.4463654 | AQ7: 1 | AR7: -3.9385016 | AS7: -3.5621624 | AT7: 1 | AU7: -4.4087615 | AV7: -4.012189 | AW7: 1 | AX7: -4.3633354 | AY7: -4.0621308 | AZ7: 1 | BA7: -4.6141711 | BB7: -4.3596676 | BC7: 1 | BD7: -5.4433793 | BE7: -5.136843 | BF7: 1 | BG7: -5.7558582 | BH7: -5.3635456 | BI7: 1 | BJ7: -6.3873845 | BK7: -5.6648003 | BL7: 1 | BM7: -7.1265058 | BN7: -6.4990407 | BO7: 1 | BP7: -7.2893742 | BQ7: -6.6245831 | BR7: 1
A8: The child was devout | B8: The child was religious | C8: The child was not religious | D8: 0 | E8: 63_0 | F8: =INDEX([1]train_xl!$H:$H,MATCH(E8,[1]train_xl!$G:$G,0)) -> as-as | G8: =INDEX([1]train_xl!$I:$I,MATCH(E8,[1]train_xl!$G:$G,0)) -> sim | H8: =INDEX([1]train_xl!$V:$V,MATCH(E8,[1]train_xl!$G:$G,0)) -> not | I8: =INDEX([2]Sheet1!$L:$L,MATCH(E8,[2]Sheet1!$I:$I,0)) -> intens | K8: -3.941186 | L8: -3.953549 | M8: 1 | N8: -4.2110816 | O8: -4.3471899 | P8: 1 | Q8: -5.1050721 | R8: -5.0278909 | S8: 0 | T8: -5.3867646 | U8: -5.3038866 | V8: 0 | W8: -6.0154251 | X8: -5.7502702 | Y8: 0 | Z8: -4.1505489 | AA8: -4.2463459 | AB8: 1 | AC8: -4.4542546 | AD8: -4.5633002 | AE8: 1 | AF8: -5.223401 | AG8: -5.1587932 | AH8: 0 | AI8: -5.8482918 | AJ8: -5.6794001 | AK8: 0 | AL8: -6.4151665 | AM8: -6.0216646 | AN8: 0 | AO8: -3.5692028 | AP8: -3.5505783 | AQ8: 0 | AR8: -3.6226195 | AS8: -3.7322904 | AT8: 1 | AU8: -4.4778205 | AV8: -4.3668464 | AW8: 0 | AX8: -4.6871018 | AY8: -4.6834519 | AZ8: 0 | BA8: -4.9852228 | BB8: -4.8299296 | BC8: 0 | BD8: -4.1672001 | BE8: -4.1477351 | BF8: 0 | BG8: -4.3432313 | BH8: -4.4550767 | BI8: 1 | BJ8: -4.9841728 | BK8: -5.1041132 | BL8: 1 | BM8: -5.6979055 | BN8: -5.5584216 | BO8: 0 | BP8: -6.254391 | BQ8: -5.8694916 | BR8: 0
A9: The child was atheistic | B9: The child was religious | C9: The child was not religious | D9: 1 | E9: 63_1 | F9: =INDEX([1]train_xl!$H:$H,MATCH(E9,[1]train_xl!$G:$G,0)) -> as-as | G9: =INDEX([1]train_xl!$I:$I,MATCH(E9,[1]train_xl!$G:$G,0)) -> sim | H9: =INDEX([1]train_xl!$V:$V,MATCH(E9,[1]train_xl!$G:$G,0)) -> not | I9: =INDEX([2]Sheet1!$L:$L,MATCH(E9,[2]Sheet1!$I:$I,0)) -> neg | K9: -3.9305518 | L9: -3.4249175 | M9: 1 | N9: -4.1648532 | O9: -3.5153604 | P9: 1 | Q9: -4.9087261 | R9: -4.2140462 | S9: 1 | T9: -4.9723632 | U9: -4.4301373 | V9: 1 | W9: -5.4153487 | X9: -4.756096 | Y9: 1 | Z9: -3.9510516 | AA9: -3.6248331 | AB9: 1 | AC9: -4.2244018 | AD9: -3.6630276 | AE9: 1 | AF9: -4.9132344 | AG9: -4.3725436 | AH9: 1 | AI9: -5.3164673 | AJ9: -4.8745563 | AK9: 1 | AL9: -5.4319499 | AM9: -4.9899631 | AN9: 1 | AO9: -3.5878454 | AP9: -3.2684923 | AQ9: 1 | AR9: -3.8752375 | AS9: -3.46633 | AT9: 1 | AU9: -4.3054402 | AV9: -3.8514731 | AW9: 1 | AX9: -4.4495075 | AY9: -4.1071718 | AZ9: 1 | BA9: -4.452092 | BB9: -4.1840329 | BC9: 1 | BD9: -4.0500691 | BE9: -3.7261821 | BF9: 1 | BG9: -4.3891563 | BH9: -3.9021978 | BI9: 1 | BJ9: -5.0820879 | BK9: -4.4992563 | BL9: 1 | BM9: -5.6960376 | BN9: -5.113608 | BO9: 1 | BP9: -5.8210391 | BQ9: -5.3806704 | BR9: 1
A10: The hangover made her feel terrible | B10: She felt bad | C10: She did not feel bad | D10: 0 | E10: 87_0 | F10: =INDEX([1]train_xl!$H:$H,MATCH(E10,[1]train_xl!$G:$G,0)) -> like | G10: =INDEX([1]train_xl!$I:$I,MATCH(E10,[1]train_xl!$G:$G,0)) -> sim | H10: =INDEX([1]train_xl!$V:$V,MATCH(E10,[1]train_xl!$G:$G,0)) -> not | I10: =INDEX([2]Sheet1!$L:$L,MATCH(E10,[2]Sheet1!$I:$I,0)) -> intens | K10: -4.2063499 | L10: -3.9243412 | M10: 0 | N10: -4.3340458 | O10: -4.1875673 | P10: 0 | Q10: -5.1958663 | R10: -4.8745532 | S10: 0 | T10: -5.7071238 | U10: -5.0496917 | V10: 0 | W10: -5.5914977 | X10: -4.9762696 | Y10: 0 | Z10: -4.084267 | AA10: -3.754929 | AB10: 0 | AC10: -4.2341881 | AD10: -4.0123358 | AE10: 0 | AF10: -5.0243638 | AG10: -4.739483 | AH10: 0 | AI10: -5.1163962 | AJ10: -4.6542143 | AK10: 0 | AL10: -5.1955408 | AM10: -4.6469509 | AN10: 0 | AO10: -3.303962 | AP10: -3.1603264 | AQ10: 0 | AR10: -3.3627972 | AS10: -3.3336459 | AT10: 0 | AU10: -4.0138094 | AV10: -3.8264275 | AW10: 0 | AX10: -4.3187756 | AY10: -4.0864258 | AZ10: 0 | BA10: -4.357547 | BB10: -4.7547973 | BC10: 1 | BD10: -4.0445988 | BE10: -3.7893233 | BF10: 0 | BG10: -4.1568159 | BH10: -4.0505254 | BI10: 0 | BJ10: -4.8740956 | BK10: -4.6750395 | BL10: 0 | BM10: -5.0762614 | BN10: -4.6024432 | BO10: 0 | BP10: -5.2377424 | BQ10: -4.7506554 | BR10: 0
A11: The hangover made her feel good | B11: She felt bad | C11: She did not feel bad | D11: 1 | E11: 87_1 | F11: =INDEX([1]train_xl!$H:$H,MATCH(E11,[1]train_xl!$G:$G,0)) -> like | G11: =INDEX([1]train_xl!$I:$I,MATCH(E11,[1]train_xl!$G:$G,0)) -> sim | H11: =INDEX([1]train_xl!$V:$V,MATCH(E11,[1]train_xl!$G:$G,0)) -> not | I11: =INDEX([2]Sheet1!$L:$L,MATCH(E11,[2]Sheet1!$I:$I,0)) -> neg | K11: -4.1159016 | L11: -3.6757533 | M11: 1 | N11: -4.5031848 | O11: -4.1404062 | P11: 1 | Q11: -5.4741118 | R11: -4.7284799 | S11: 1 | T11: -5.3871571 | U11: -4.8306046 | V11: 1 | W11: -5.6104273 | X11: -5.1121792 | Y11: 1 | Z11: -3.9025462 | AA11: -3.509488 | AB11: 1 | AC11: -4.2052413 | AD11: -3.862592 | AE11: 1 | AF11: -5.1923943 | AG11: -4.5246439 | AH11: 1 | AI11: -5.1464216 | AJ11: -4.595818 | AK11: 1 | AL11: -5.4012828 | AM11: -4.8883707 | AN11: 1 | AO11: -3.434574 | AP11: -3.1184697 | AQ11: 1 | AR11: -3.64487 | AS11: -3.4174353 | AT11: 1 | AU11: -4.4046495 | AV11: -3.8794013 | AW11: 1 | AX11: -4.4417027 | AY11: -4.0819121 | AZ11: 1 | BA11: -4.582843 | BB11: -4.890966 | BC11: 0 | BD11: -3.9515062 | BE11: -3.5220769 | BF11: 1 | BG11: -4.1634343 | BH11: -3.8418518 | BI11: 1 | BJ11: -5.1390052 | BK11: -4.4972623 | BL11: 1 | BM11: -5.0754684 | BN11: -4.5702988 | BO11: 1 | BP11: -5.3785805 | BQ11: -4.8399958 | BR11: 1
A12: The room was unenclosed | B12: The room was open | C12: The room was not open | D12: 0 | E12: 89_0 | F12: =INDEX([1]train_xl!$H:$H,MATCH(E12,[1]train_xl!$G:$G,0)) -> as-as | G12: =INDEX([1]train_xl!$I:$I,MATCH(E12,[1]train_xl!$G:$G,0)) -> sim | H12: =INDEX([1]train_xl!$V:$V,MATCH(E12,[1]train_xl!$G:$G,0)) -> not | I12: =INDEX([2]Sheet1!$L:$L,MATCH(E12,[2]Sheet1!$I:$I,0)) -> intens | K12: -3.9750089 | L12: -4.0373355 | M12: 1 | N12: -3.9546864 | O12: -4.1481295 | P12: 1 | Q12: -4.6857446 | R12: -4.7722778 | S12: 1 | T12: -4.9658684 | U12: -4.9761823 | V12: 1 | W12: -5.3983515 | X12: -5.2634082 | Y12: 0 | Z12: -3.8202848 | AA12: -3.9770806 | AB12: 1 | AC12: -3.890411 | AD12: -4.1335024 | AE12: 1 | AF12: -4.5358801 | AG12: -4.7010646 | AH12: 1 | AI12: -4.942652 | AJ12: -4.8544651 | AK12: 0 | AL12: -5.2723393 | AM12: -5.1258457 | AN12: 0 | AO12: -3.3477987 | AP12: -3.5265397 | AQ12: 1 | AR12: -3.3400736 | AS12: -3.632601 | AT12: 1 | AU12: -3.8417813 | AV12: -4.018902 | AW12: 1 | AX12: -3.942774 | AY12: -4.037555 | AZ12: 1 | BA12: -4.3393957 | BB12: -4.261554 | BC12: 0 | BD12: -3.9602566 | BE12: -4.104999 | BF12: 1 | BG12: -4.0788185 | BH12: -4.3179543 | BI12: 1 | BJ12: -4.723841 | BK12: -4.8196571 | BL12: 1 | BM12: -5.2918263 | BN12: -5.1972403 | BO12: 0 | BP12: -5.7083241 | BQ12: -5.4760786 | BR12: 0
A13: The room was enclosed | B13: The room was open | C13: The room was not open | D13: 1 | E13: 89_1 | F13: =INDEX([1]train_xl!$H:$H,MATCH(E13,[1]train_xl!$G:$G,0)) -> as-as | G13: =INDEX([1]train_xl!$I:$I,MATCH(E13,[1]train_xl!$G:$G,0)) -> sim | H13: =INDEX([1]train_xl!$V:$V,MATCH(E13,[1]train_xl!$G:$G,0)) -> not | I13: =INDEX([2]Sheet1!$L:$L,MATCH(E13,[2]Sheet1!$I:$I,0)) -> neg | K13: -4.292913 | L13: -3.8690768 | M13: 1 | N13: -4.4930376 | O13: -4.0005557 | P13: 1 | Q13: -5.3158571 | R13: -4.692081 | S13: 1 | T13: -5.3584551 | U13: -5.0716504 | V13: 1 | W13: -5.9724519 | X13: -5.614173 | Y13: 1 | Z13: -4.7230076 | AA13: -4.1467091 | AB13: 1 | AC13: -4.9851789 | AD13: -4.3703204 | AE13: 1 | AF13: -5.8088895 | AG13: -4.9875391 | AH13: 1 | AI13: -5.9363359 | AJ13: -5.4822957 | AK13: 1 | AL13: -6.2606793 | AM13: -5.7778102 | AN13: 1 | AO13: -3.991225 | AP13: -3.498021 | AQ13: 1 | AR13: -4.1188851 | AS13: -3.5596828 | AT13: 1 | AU13: -4.5803659 | AV13: -3.9733635 | AW13: 1 | AX13: -4.6017278 | AY13: -4.3646105 | AZ13: 1 | BA13: -5.0146022 | BB13: -4.7047569 | BC13: 1 | BD13: -4.7380179 | BE13: -4.153413 | BF13: 1 | BG13: -5.058124 | BH13: -4.4390299 | BI13: 1 | BJ13: -5.8401484 | BK13: -5.0366305 | BL13: 1 | BM13: -5.9067127 | BN13: -5.5623495 | BO13: 1 | BP13: -6.3227246 | BQ13: -5.8540003 | BR13: 1
... A257: That monster was harmless | B257: That monster was scary | C257: That monster was not scary | D257: 1 | E257: X39_1 | F257: =INDEX([1]train_xl!$H:$H,MATCH(E257,[1]train_xl!$G:$G,0)) -> as-as | G257: =INDEX([1]train_xl!$I:$I,MATCH(E257,[1]train_xl!$G:$G,0)) -> sim | H257: =INDEX([1]train_xl!$V:$V,MATCH(E257,[1]train_xl!$G:$G,0)) -> not | I257: =INDEX([2]Sheet1!$L:$L,MATCH(E257,[2]Sheet1!$I:$I,0)) -> neg | K257: -4.2580018 | L257: -3.830239 | M257: 1 | N257: -4.6508619 | O257: -3.878349 | P257: 1 | Q257: -5.3037884 | R257: -4.6572113 | S257: 1 | T257: -4.8329494 | U257: -4.5325692 | V257: 1 | W257: -5.1165774 | X257: -4.7589663 | Y257: 1 | Z257: -5.2435965 | AA257: -4.7449049 | AB257: 1 | AC257: -5.5118278 | AD257: -4.7583961 | AE257: 1 | AF257: -6.2038482 | AG257: -5.5664552 | AH257: 1 | AI257: -6.2996677 | AJ257: -5.801899 | AK257: 1 | AL257: -6.4148054 | AM257: -5.9255136 | AN257: 1 | AO257: -4.5337416 | AP257: -4.0780561 | AQ257: 1 | AR257: -4.6794109 | AS257: -4.071267 | AT257: 1 | AU257: -5.5273368 | AV257: -4.9097967 | AW257: 1 | AX257: -5.6462607 | AY257: -4.8882245 | AZ257: 1 | BA257: -5.5969648 | BB257: -5.089631 | BC257: 1 | BD257: -5.2591001 | BE257: -4.7646234 | BF257: 1 | BG257: -5.5447469 | BH257: -4.678213 | BI257: 1 | BJ257: -6.173773 | BK257: -5.5083382 | BL257: 1 | BM257: -6.2430016 | BN257: -5.7679123 | BO257: 1 | BP257: -6.5346558 | BQ257: -6.0408889 | BR257: 1

Sheet Summary
C1: all | D1: sim neg | E1: sim intens | F1: neg not | G1: intens not | H1: neg antonym | I1: intens antonym
A2: 3 | B2: {=LEFT(INDEX(test_output!K:FU,1,A2),LEN(INDEX(test_output!K:FU,1,A2))-4)} -> Llama-3-70B-Instruct M1 | C2: =AVERAGE(INDEX(test_output!K:FZ,0,A2)) -> 0.79296875 | D2: {=AVERAGE(_xlfn._xlws.FILTER(INDEX(test_output!K:FZ,0,A2),test_output!I:I="neg"))} -> 0.953125 | E2: {=AVERAGE(_xlfn._xlws.FILTER(INDEX(test_output!K:FZ,0,A2),test_output!I:I="intens"))} -> 0.6328125 | F2: {=AVERAGE(_xlfn._xlws.FILTER(INDEX(test_output!K:FZ,0,A2),(test_output!I:I="neg")*(test_output!H:H="not")))} -> 0.96261682 | G2: {=AVERAGE(_xlfn._xlws.FILTER(INDEX(test_output!K:FZ,0,A2),(test_output!I:I="intens")*(test_output!H:H="not")))} -> 0.63551402 | H2: {=AVERAGE(_xlfn._xlws.FILTER(INDEX(test_output!K:FZ,0,A2),(test_output!I:I="neg")*(test_output!H:H="antonym")))} -> 0.89473684 | I2: {=AVERAGE(_xlfn._xlws.FILTER(INDEX(test_output!K:FZ,0,A2),(test_output!I:I="intens")*(test_output!H:H="antonym")))} -> 0.57894737
A3: =A2+3 -> 6 | B3: {=LEFT(INDEX(test_output!K:FU,1,A3),LEN(INDEX(test_output!K:FU,1,A3))-4)} -> Llama-3-70B-Instruct M2 | C3: =AVERAGE(INDEX(test_output!K:FZ,0,A3)) -> 0.82421875 | D3: {=AVERAGE(_xlfn._xlws.FILTER(INDEX(test_output!K:FZ,0,A3),test_output!I:I="neg"))} -> 0.9609375 | E3: {=AVERAGE(_xlfn._xlws.FILTER(INDEX(test_output!K:FZ,0,A3),test_output!I:I="intens"))} -> 0.6875 | F3: {=AVERAGE(_xlfn._xlws.FILTER(INDEX(test_output!K:FZ,0,A3),(test_output!I:I="neg")*(test_output!H:H="not")))} -> 0.97196262 | G3: {=AVERAGE(_xlfn._xlws.FILTER(INDEX(test_output!K:FZ,0,A3),(test_output!I:I="intens")*(test_output!H:H="not")))} -> 0.70093458 | H3: {=AVERAGE(_xlfn._xlws.FILTER(INDEX(test_output!K:FZ,0,A3),(test_output!I:I="neg")*(test_output!H:H="antonym")))} -> 0.89473684 | I3: {=AVERAGE(_xlfn._xlws.FILTER(INDEX(test_output!K:FZ,0,A3),(test_output!I:I="intens")*(test_output!H:H="antonym")))} -> 0.57894737
A4: =A3+3 -> 9 | B4: {=LEFT(INDEX(test_output!K:FU,1,A4),LEN(INDEX(test_output!K:FU,1,A4))-4)} -> Llama-3-70B-Instruct M3 | C4: =AVERAGE(INDEX(test_output!K:FZ,0,A4)) -> 0.7578125 | D4: {=AVERAGE(_xlfn._xlws.FILTER(INDEX(test_output!K:FZ,0,A4),test_output!I:I="neg"))} -> 0.9609375 | E4: {=AVERAGE(_xlfn._xlws.FILTER(INDEX(test_output!K:FZ,0,A4),test_output!I:I="intens"))} -> 0.5546875 | F4: {=AVERAGE(_xlfn._xlws.FILTER(INDEX(test_output!K:FZ,0,A4),(test_output!I:I="neg")*(test_output!H:H="not")))} -> 0.97196262 | G4: {=AVERAGE(_xlfn._xlws.FILTER(INDEX(test_output!K:FZ,0,A4),(test_output!I:I="intens")*(test_output!H:H="not")))} -> 0.55140187 | H4: {=AVERAGE(_xlfn._xlws.FILTER(INDEX(test_output!K:FZ,0,A4),(test_output!I:I="neg")*(test_output!H:H="antonym")))} -> 0.89473684 | I4: {=AVERAGE(_xlfn._xlws.FILTER(INDEX(test_output!K:FZ,0,A4),(test_output!I:I="intens")*(test_output!H:H="antonym")))} -> 0.52631579
A5: =A4+3 -> 12 | B5: {=LEFT(INDEX(test_output!K:FU,1,A5),LEN(INDEX(test_output!K:FU,1,A5))-4)} -> Llama-3-70B-Instruct M4 | C5: =AVERAGE(INDEX(test_output!K:FZ,0,A5)) -> 0.7109375 | D5: {=AVERAGE(_xlfn._xlws.FILTER(INDEX(test_output!K:FZ,0,A5),test_output!I:I="neg"))} -> 0.890625 | E5: {=AVERAGE(_xlfn._xlws.FILTER(INDEX(test_output!K:FZ,0,A5),test_output!I:I="intens"))} -> 0.53125 | F5: {=AVERAGE(_xlfn._xlws.FILTER(INDEX(test_output!K:FZ,0,A5),(test_output!I:I="neg")*(test_output!H:H="not")))} -> 0.90654206 | G5: {=AVERAGE(_xlfn._xlws.FILTER(INDEX(test_output!K:FZ,0,A5),(test_output!I:I="intens")*(test_output!H:H="not")))} -> 0.51401869 | H5: {=AVERAGE(_xlfn._xlws.FILTER(INDEX(test_output!K:FZ,0,A5),(test_output!I:I="neg")*(test_output!H:H="antonym")))} -> 0.78947368 | I5: {=AVERAGE(_xlfn._xlws.FILTER(INDEX(test_output!K:FZ,0,A5),(test_output!I:I="intens")*(test_output!H:H="antonym")))} -> 0.57894737
A6: =A5+3 -> 15 | B6: {=LEFT(INDEX(test_output!K:FU,1,A6),LEN(INDEX(test_output!K:FU,1,A6))-4)} -> Llama-3-70B-Instruct M5 | C6: =AVERAGE(INDEX(test_output!K:FZ,0,A6)) -> 0.5703125 | D6: {=AVERAGE(_xlfn._xlws.FILTER(INDEX(test_output!K:FZ,0,A6),test_output!I:I="neg"))} -> 0.890625 | E6: {=AVERAGE(_xlfn._xlws.FILTER(INDEX(test_output!K:FZ,0,A6),test_output!I:I="intens"))} -> 0.25 | F6: {=AVERAGE(_xlfn._xlws.FILTER(INDEX(test_output!K:FZ,0,A6),(test_output!I:I="neg")*(test_output!H:H="not")))} -> 0.90654206 | G6: {=AVERAGE(_xlfn._xlws.FILTER(INDEX(test_output!K:FZ,0,A6),(test_output!I:I="intens")*(test_output!H:H="not")))} -> 0.23364486 | H6: {=AVERAGE(_xlfn._xlws.FILTER(INDEX(test_output!K:FZ,0,A6),(test_output!I:I="neg")*(test_output!H:H="antonym")))} -> 0.78947368 | I6: {=AVERAGE(_xlfn._xlws.FILTER(INDEX(test_output!K:FZ,0,A6),(test_output!I:I="intens")*(test_output!H:H="antonym")))} -> 0.36842105
A7: =A6+3 -> 18 | B7: {=LEFT(INDEX(test_output!K:FU,1,A7),LEN(INDEX(test_output!K:FU,1,A7))-4)} -> Llama-3.1-70B-Instruct M1 | C7: =AVERAGE(INDEX(test_output!K:FZ,0,A7)) -> 0.75 | D7: {=AVERAGE(_xlfn._xlws.FILTER(INDEX(test_output!K:FZ,0,A7),test_output!I:I="neg"))} -> 0.9453125 | E7: {=AVERAGE(_xlfn._xlws.FILTER(INDEX(test_output!K:FZ,0,A7),test_output!I:I="intens"))} -> 0.5546875 | F7: {=AVERAGE(_xlfn._xlws.FILTER(INDEX(test_output!K:FZ,0,A7),(test_output!I:I="neg")*(test_output!H:H="not")))} -> 0.94392523 | G7: {=AVERAGE(_xlfn._xlws.FILTER(INDEX(test_output!K:FZ,0,A7),(test_output!I:I="intens")*(test_output!H:H="not")))} -> 0.55140187 | H7: {=AVERAGE(_xlfn._xlws.FILTER(INDEX(test_output!K:FZ,0,A7),(test_output!I:I="neg")*(test_output!H:H="antonym")))} -> 0.94736842 | I7: {=AVERAGE(_xlfn._xlws.FILTER(INDEX(test_output!K:FZ,0,A7),(test_output!I:I="intens")*(test_output!H:H="antonym")))} -> 0.52631579
A8: =A7+3 -> 21 | B8: {=LEFT(INDEX(test_output!K:FU,1,A8),LEN(INDEX(test_output!K:FU,1,A8))-4)} -> Llama-3.1-70B-Instruct M2 | C8: =AVERAGE(INDEX(test_output!K:FZ,0,A8)) -> 0.79296875 | D8: {=AVERAGE(_xlfn._xlws.FILTER(INDEX(test_output!K:FZ,0,A8),test_output!I:I="neg"))} -> 0.96875 | E8: {=AVERAGE(_xlfn._xlws.FILTER(INDEX(test_output!K:FZ,0,A8),test_output!I:I="intens"))} -> 0.6171875 | F8: {=AVERAGE(_xlfn._xlws.FILTER(INDEX(test_output!K:FZ,0,A8),(test_output!I:I="neg")*(test_output!H:H="not")))} -> 0.98130841 | G8: {=AVERAGE(_xlfn._xlws.FILTER(INDEX(test_output!K:FZ,0,A8),(test_output!I:I="intens")*(test_output!H:H="not")))} -> 0.64485981 | H8: {=AVERAGE(_xlfn._xlws.FILTER(INDEX(test_output!K:FZ,0,A8),(test_output!I:I="neg")*(test_output!H:H="antonym")))} -> 0.89473684 | I8: {=AVERAGE(_xlfn._xlws.FILTER(INDEX(test_output!K:FZ,0,A8),(test_output!I:I="intens")*(test_output!H:H="antonym")))} -> 0.42105263
A9: =A8+3 -> 24 | B9: {=LEFT(INDEX(test_output!K:FU,1,A9),LEN(INDEX(test_output!K:FU,1,A9))-4)} -> Llama-3.1-70B-Instruct M3 | C9: =AVERAGE(INDEX(test_output!K:FZ,0,A9)) -> 0.71484375 | D9: {=AVERAGE(_xlfn._xlws.FILTER(INDEX(test_output!K:FZ,0,A9),test_output!I:I="neg"))} -> 0.96875 | E9: {=AVERAGE(_xlfn._xlws.FILTER(INDEX(test_output!K:FZ,0,A9),test_output!I:I="intens"))} -> 0.4609375 | F9: {=AVERAGE(_xlfn._xlws.FILTER(INDEX(test_output!K:FZ,0,A9),(test_output!I:I="neg")*(test_output!H:H="not")))} -> 0.98130841 | G9: {=AVERAGE(_xlfn._xlws.FILTER(INDEX(test_output!K:FZ,0,A9),(test_output!I:I="intens")*(test_output!H:H="not")))} -> 0.4953271 | H9: {=AVERAGE(_xlfn._xlws.FILTER(INDEX(test_output!K:FZ,0,A9),(test_output!I:I="neg")*(test_output!H:H="antonym")))} -> 0.89473684 | I9: {=AVERAGE(_xlfn._xlws.FILTER(INDEX(test_output!K:FZ,0,A9),(test_output!I:I="intens")*(test_output!H:H="antonym")))} -> 0.26315789
A10: =A9+3 -> 27 | B10: {=LEFT(INDEX(test_output!K:FU,1,A10),LEN(INDEX(test_output!K:FU,1,A10))-4)} -> Llama-3.1-70B-Instruct M4 | C10: =AVERAGE(INDEX(test_output!K:FZ,0,A10)) -> 0.64453125 | D10: {=AVERAGE(_xlfn._xlws.FILTER(INDEX(test_output!K:FZ,0,A10),test_output!I:I="neg"))} -> 0.9140625 | E10: {=AVERAGE(_xlfn._xlws.FILTER(INDEX(test_output!K:FZ,0,A10),test_output!I:I="intens"))} -> 0.375 | F10: {=AVERAGE(_xlfn._xlws.FILTER(INDEX(test_output!K:FZ,0,A10),(test_output!I:I="neg")*(test_output!H:H="not")))} -> 0.92523364 | G10: {=AVERAGE(_xlfn._xlws.FILTER(INDEX(test_output!K:FZ,0,A10),(test_output!I:I="intens")*(test_output!H:H="not")))} -> 0.39252336 | H10: {=AVERAGE(_xlfn._xlws.FILTER(INDEX(test_output!K:FZ,0,A10),(test_output!I:I="neg")*(test_output!H:H="antonym")))} -> 0.84210526 | I10: {=AVERAGE(_xlfn._xlws.FILTER(INDEX(test_output!K:FZ,0,A10),(test_output!I:I="intens")*(test_output!H:H="antonym")))} -> 0.26315789
A11: =A10+3 -> 30 | B11: {=LEFT(INDEX(test_output!K:FU,1,A11),LEN(INDEX(test_output!K:FU,1,A11))-4)} -> Llama-3.1-70B-Instruct M5 | C11: =AVERAGE(INDEX(test_output!K:FZ,0,A11)) -> 0.5625 | D11: {=AVERAGE(_xlfn._xlws.FILTER(INDEX(test_output!K:FZ,0,A11),test_output!I:I="neg"))} -> 0.9296875 | E11: {=AVERAGE(_xlfn._xlws.FILTER(INDEX(test_output!K:FZ,0,A11),test_output!I:I="intens"))} -> 0.1953125 | F11: {=AVERAGE(_xlfn._xlws.FILTER(INDEX(test_output!K:FZ,0,A11),(test_output!I:I="neg")*(test_output!H:H="not")))} -> 0.93457944 | G11: {=AVERAGE(_xlfn._xlws.FILTER(INDEX(test_output!K:FZ,0,A11),(test_output!I:I="intens")*(test_output!H:H="not")))} -> 0.20560748 | H11: {=AVERAGE(_xlfn._xlws.FILTER(INDEX(test_output!K:FZ,0,A11),(test_output!I:I="neg")*(test_output!H:H="antonym")))} -> 0.89473684 | I11: {=AVERAGE(_xlfn._xlws.FILTER(INDEX(test_output!K:FZ,0,A11),(test_output!I:I="intens")*(test_output!H:H="antonym")))} -> 0.15789474
A12: =A11+3 -> 33 | B12: {=LEFT(INDEX(test_output!K:FU,1,A12),LEN(INDEX(test_output!K:FU,1,A12))-4)} -> Llama-3.1-405B-Instruct M1 | C12: =AVERAGE(INDEX(test_output!K:FZ,0,A12)) -> 0.8046875 | D12: {=AVERAGE(_xlfn._xlws.FILTER(INDEX(test_output!K:FZ,0,A12),test_output!I:I="neg"))} -> 0.953125 | E12: {=AVERAGE(_xlfn._xlws.FILTER(INDEX(test_output!K:FZ,0,A12),test_output!I:I="intens"))} -> 0.65625 | F12: {=AVERAGE(_xlfn._xlws.FILTER(INDEX(test_output!K:FZ,0,A12),(test_output!I:I="neg")*(test_output!H:H="not")))} -> 0.96261682 | G12: {=AVERAGE(_xlfn._xlws.FILTER(INDEX(test_output!K:FZ,0,A12),(test_output!I:I="intens")*(test_output!H:H="not")))} -> 0.65420561 | H12: {=AVERAGE(_xlfn._xlws.FILTER(INDEX(test_output!K:FZ,0,A12),(test_output!I:I="neg")*(test_output!H:H="antonym")))} -> 0.89473684 | I12: {=AVERAGE(_xlfn._xlws.FILTER(INDEX(test_output!K:FZ,0,A12),(test_output!I:I="intens")*(test_output!H:H="antonym")))} -> 0.63157895
A13: =A12+3 -> 36 | B13: {=LEFT(INDEX(test_output!K:FU,1,A13),LEN(INDEX(test_output!K:FU,1,A13))-4)} -> Llama-3.1-405B-Instruct M2 | C13: =AVERAGE(INDEX(test_output!K:FZ,0,A13)) -> 0.85546875 | D13: {=AVERAGE(_xlfn._xlws.FILTER(INDEX(test_output!K:FZ,0,A13),test_output!I:I="neg"))} -> 0.96875 | E13: {=AVERAGE(_xlfn._xlws.FILTER(INDEX(test_output!K:FZ,0,A13),test_output!I:I="intens"))} -> 0.7421875 | F13: {=AVERAGE(_xlfn._xlws.FILTER(INDEX(test_output!K:FZ,0,A13),(test_output!I:I="neg")*(test_output!H:H="not")))} -> 0.98130841 | G13: {=AVERAGE(_xlfn._xlws.FILTER(INDEX(test_output!K:FZ,0,A13),(test_output!I:I="intens")*(test_output!H:H="not")))} -> 0.76635514 | H13: {=AVERAGE(_xlfn._xlws.FILTER(INDEX(test_output!K:FZ,0,A13),(test_output!I:I="neg")*(test_output!H:H="antonym")))} -> 0.89473684 | I13: {=AVERAGE(_xlfn._xlws.FILTER(INDEX(test_output!K:FZ,0,A13),(test_output!I:I="intens")*(test_output!H:H="antonym")))} -> 0.57894737
A14: =A13+3 -> 39 | B14: {=LEFT(INDEX(test_output!K:FU,1,A14),LEN(INDEX(test_output!K:FU,1,A14))-4)} -> Llama-3.1-405B-Instruct M3 | C14: =AVERAGE(INDEX(test_output!K:FZ,0,A14)) -> 0.765625 | D14: {=AVERAGE(_xlfn._xlws.FILTER(INDEX(test_output!K:FZ,0,A14),test_output!I:I="neg"))} -> 0.9609375 | E14: {=AVERAGE(_xlfn._xlws.FILTER(INDEX(test_output!K:FZ,0,A14),test_output!I:I="intens"))} -> 0.5703125 | F14: {=AVERAGE(_xlfn._xlws.FILTER(INDEX(test_output!K:FZ,0,A14),(test_output!I:I="neg")*(test_output!H:H="not")))} -> 0.97196262 | G14: {=AVERAGE(_xlfn._xlws.FILTER(INDEX(test_output!K:FZ,0,A14),(test_output!I:I="intens")*(test_output!H:H="not")))} -> 0.58878505 | H14: {=AVERAGE(_xlfn._xlws.FILTER(INDEX(test_output!K:FZ,0,A14),(test_output!I:I="neg")*(test_output!H:H="antonym")))} -> 0.89473684 | I14: {=AVERAGE(_xlfn._xlws.FILTER(INDEX(test_output!K:FZ,0,A14),(test_output!I:I="intens")*(test_output!H:H="antonym")))} -> 0.42105263
... A21: =A20+3 -> 60 | B21: {=LEFT(INDEX(test_output!K:FU,1,A21),LEN(INDEX(test_output!K:FU,1,A21))-4)} -> Llama-3.3-70B-Instruct M5 | C21: =AVERAGE(INDEX(test_output!K:FZ,0,A21)) -> 0.55078125 | D21: {=AVERAGE(_xlfn._xlws.FILTER(INDEX(test_output!K:FZ,0,A21),test_output!I:I="neg"))} -> 0.921875 | E21: {=AVERAGE(_xlfn._xlws.FILTER(INDEX(test_output!K:FZ,0,A21),test_output!I:I="intens"))} -> 0.1796875 | F21: {=AVERAGE(_xlfn._xlws.FILTER(INDEX(test_output!K:FZ,0,A21),(test_output!I:I="neg")*(test_output!H:H="not")))} -> 0.92523364 | G21: {=AVERAGE(_xlfn._xlws.FILTER(INDEX(test_output!K:FZ,0,A21),(test_output!I:I="intens")*(test_output!H:H="not")))} -> 0.18691589 | H21: {=AVERAGE(_xlfn._xlws.FILTER(INDEX(test_output!K:FZ,0,A21),(test_output!I:I="neg")*(test_output!H:H="antonym")))} -> 0.89473684 | I21: {=AVERAGE(_xlfn._xlws.FILTER(INDEX(test_output!K:FZ,0,A21),(test_output!I:I="intens")*(test_output!H:H="antonym")))} -> 0.15789474
A22: =A21+3 -> 63 | B22: {=LEFT(INDEX(test_output!K:FU,1,A22),LEN(INDEX(test_output!K:FU,1,A22))-4)} -> #VALUE! | C22: =AVERAGE(INDEX(test_output!K:FT,0,A22)) -> #DIV/0! | D22: {=AVERAGE(_xlfn._xlws.FILTER(INDEX(test_output!K:FT,0,A22),[1]train_xl!$I:$I="met"))} -> #DIV/0! | E22: {=AVERAGE(_xlfn._xlws.FILTER(INDEX(test_output!K:FT,0,A22),[1]train_xl!$I:$I="sim"))} -> #DIV/0! | F22: {=AVERAGE(_xlfn._xlws.FILTER(INDEX(test_output!K:FT,0,A22),[1]train_xl!$Y:$Y="not neg pair"))} -> #VALUE! | G22: {=AVERAGE(_xlfn._xlws.FILTER(INDEX(test_output!K:FT,0,A22),[1]train_xl!$Z:$Z=1))} -> #VALUE! | H22: {=AVERAGE(_xlfn._xlws.FILTER(INDEX(test_output!K:FT,0,A22),[1]train_xl!$AA:$AA="neg"))} -> #VALUE! | I22: {=AVERAGE(_xlfn._xlws.FILTER(INDEX(test_output!K:FT,0,A22),[1]train_xl!$AA:$AA="intens"))} -> #VALUE!
A23: =A22+3 -> 66 | B23: {=LEFT(INDEX(test_output!K:FU,1,A23),LEN(INDEX(test_output!K:FU,1,A23))-4)} -> #VALUE! | C23: =AVERAGE(INDEX(test_output!K:FT,0,A23)) -> #DIV/0! | D23: {=AVERAGE(_xlfn._xlws.FILTER(INDEX(test_output!K:FT,0,A23),[1]train_xl!$I:$I="met"))} -> #DIV/0! | E23: {=AVERAGE(_xlfn._xlws.FILTER(INDEX(test_output!K:FT,0,A23),[1]train_xl!$I:$I="sim"))} -> #DIV/0! | F23: {=AVERAGE(_xlfn._xlws.FILTER(INDEX(test_output!K:FT,0,A23),[1]train_xl!$Y:$Y="not neg pair"))} -> #VALUE! | G23: {=AVERAGE(_xlfn._xlws.FILTER(INDEX(test_output!K:FT,0,A23),[1]train_xl!$Z:$Z=1))} -> #VALUE! | H23: {=AVERAGE(_xlfn._xlws.FILTER(INDEX(test_output!K:FT,0,A23),[1]train_xl!$AA:$AA="neg"))} -> #VALUE! | I23: {=AVERAGE(_xlfn._xlws.FILTER(INDEX(test_output!K:FT,0,A23),[1]train_xl!$AA:$AA="intens"))} -> #VALUE!
A24: =A23+3 -> 69 | B24: {=LEFT(INDEX(test_output!K:FU,1,A24),LEN(INDEX(test_output!K:FU,1,A24))-4)} -> #VALUE! | C24: =AVERAGE(INDEX(test_output!K:FT,0,A24)) -> #DIV/0! | D24: {=AVERAGE(_xlfn._xlws.FILTER(INDEX(test_output!K:FT,0,A24),[1]train_xl!$I:$I="met"))} -> #DIV/0! | E24: {=AVERAGE(_xlfn._xlws.FILTER(INDEX(test_output!K:FT,0,A24),[1]train_xl!$I:$I="sim"))} -> #DIV/0! | F24: {=AVERAGE(_xlfn._xlws.FILTER(INDEX(test_output!K:FT,0,A24),[1]train_xl!$Y:$Y="not neg pair"))} -> #VALUE! | G24: {=AVERAGE(_xlfn._xlws.FILTER(INDEX(test_output!K:FT,0,A24),[1]train_xl!$Z:$Z=1))} -> #VALUE! | H24: {=AVERAGE(_xlfn._xlws.FILTER(INDEX(test_output!K:FT,0,A24),[1]train_xl!$AA:$AA="neg"))} -> #VALUE! | I24: {=AVERAGE(_xlfn._xlws.FILTER(INDEX(test_output!K:FT,0,A24),[1]train_xl!$AA:$AA="intens"))} -> #VALUE!
A25: =A24+3 -> 72 | B25: {=LEFT(INDEX(test_output!K:FU,1,A25),LEN(INDEX(test_output!K:FU,1,A25))-4)} -> #VALUE! | C25: =AVERAGE(INDEX(test_output!K:FT,0,A25)) -> #DIV/0! | D25: {=AVERAGE(_xlfn._xlws.FILTER(INDEX(test_output!K:FT,0,A25),[1]train_xl!$I:$I="met"))} -> #DIV/0! | E25: {=AVERAGE(_xlfn._xlws.FILTER(INDEX(test_output!K:FT,0,A25),[1]train_xl!$I:$I="sim"))} -> #DIV/0! | F25: {=AVERAGE(_xlfn._xlws.FILTER(INDEX(test_output!K:FT,0,A25),[1]train_xl!$Y:$Y="not neg pair"))} -> #VALUE! | G25: {=AVERAGE(_xlfn._xlws.FILTER(INDEX(test_output!K:FT,0,A25),[1]train_xl!$Z:$Z=1))} -> #VALUE! | H25: {=AVERAGE(_xlfn._xlws.FILTER(INDEX(test_output!K:FT,0,A25),[1]train_xl!$AA:$AA="neg"))} -> #VALUE! | I25: {=AVERAGE(_xlfn._xlws.FILTER(INDEX(test_output!K:FT,0,A25),[1]train_xl!$AA:$AA="intens"))} -> #VALUE!
A26: =A25+3 -> 75 | B26: {=LEFT(INDEX(test_output!K:FU,1,A26),LEN(INDEX(test_output!K:FU,1,A26))-4)} -> #VALUE! | C26: =AVERAGE(INDEX(test_output!K:FT,0,A26)) -> #DIV/0! | D26: {=AVERAGE(_xlfn._xlws.FILTER(INDEX(test_output!K:FT,0,A26),[1]train_xl!$I:$I="met"))} -> #DIV/0! | E26: {=AVERAGE(_xlfn._xlws.FILTER(INDEX(test_output!K:FT,0,A26),[1]train_xl!$I:$I="sim"))} -> #DIV/0! | F26: {=AVERAGE(_xlfn._xlws.FILTER(INDEX(test_output!K:FT,0,A26),[1]train_xl!$Y:$Y="not neg pair"))} -> #VALUE! | G26: {=AVERAGE(_xlfn._xlws.FILTER(INDEX(test_output!K:FT,0,A26),[1]train_xl!$Z:$Z=1))} -> #VALUE! | H26: {=AVERAGE(_xlfn._xlws.FILTER(INDEX(test_output!K:FT,0,A26),[1]train_xl!$AA:$AA="neg"))} -> #VALUE! | I26: {=AVERAGE(_xlfn._xlws.FILTER(INDEX(test_output!K:FT,0,A26),[1]train_xl!$AA:$AA="intens"))} -> #VALUE!
A27: =A26+3 -> 78 | B27: {=LEFT(INDEX(test_output!K:FU,1,A27),LEN(INDEX(test_output!K:FU,1,A27))-4)} -> #VALUE! | C27: =AVERAGE(INDEX(test_output!K:FT,0,A27)) -> #DIV/0! | D27: {=AVERAGE(_xlfn._xlws.FILTER(INDEX(test_output!K:FT,0,A27),[1]train_xl!$I:$I="met"))} -> #DIV/0! | E27: {=AVERAGE(_xlfn._xlws.FILTER(INDEX(test_output!K:FT,0,A27),[1]train_xl!$I:$I="sim"))} -> #DIV/0! | F27: {=AVERAGE(_xlfn._xlws.FILTER(INDEX(test_output!K:FT,0,A27),[1]train_xl!$Y:$Y="not neg pair"))} -> #VALUE! | G27: {=AVERAGE(_xlfn._xlws.FILTER(INDEX(test_output!K:FT,0,A27),[1]train_xl!$Z:$Z=1))} -> #VALUE! | H27: {=AVERAGE(_xlfn._xlws.FILTER(INDEX(test_output!K:FT,0,A27),[1]train_xl!$AA:$AA="neg"))} -> #VALUE! | I27: {=AVERAGE(_xlfn._xlws.FILTER(INDEX(test_output!K:FT,0,A27),[1]train_xl!$AA:$AA="intens"))} -> #VALUE!
A28: =A27+3 -> 81 | B28: {=LEFT(INDEX(test_output!K:FU,1,A28),LEN(INDEX(test_output!K:FU,1,A28))-4)} -> #VALUE! | C28: =AVERAGE(INDEX(test_output!K:FT,0,A28)) -> #DIV/0! | D28: {=AVERAGE(_xlfn._xlws.FILTER(INDEX(test_output!K:FT,0,A28),[1]train_xl!$I:$I="met"))} -> #DIV/0! | E28: {=AVERAGE(_xlfn._xlws.FILTER(INDEX(test_output!K:FT,0,A28),[1]train_xl!$I:$I="sim"))} -> #DIV/0! | F28: {=AVERAGE(_xlfn._xlws.FILTER(INDEX(test_output!K:FT,0,A28),[1]train_xl!$Y:$Y="not neg pair"))} -> #VALUE! | G28: {=AVERAGE(_xlfn._xlws.FILTER(INDEX(test_output!K:FT,0,A28),[1]train_xl!$Z:$Z=1))} -> #VALUE! | H28: {=AVERAGE(_xlfn._xlws.FILTER(INDEX(test_output!K:FT,0,A28),[1]train_xl!$AA:$AA="neg"))} -> #VALUE! | I28: {=AVERAGE(_xlfn._xlws.FILTER(INDEX(test_output!K:FT,0,A28),[1]train_xl!$AA:$AA="intens"))} -> #VALUE!
A29: =A28+3 -> 84 | B29: {=LEFT(INDEX(test_output!K:FU,1,A29),LEN(INDEX(test_output!K:FU,1,A29))-4)} -> #VALUE! | C29: =AVERAGE(INDEX(test_output!K:FT,0,A29)) -> #DIV/0! | D29: {=AVERAGE(_xlfn._xlws.FILTER(INDEX(test_output!K:FT,0,A29),[1]train_xl!$I:$I="met"))} -> #DIV/0! | E29: {=AVERAGE(_xlfn._xlws.FILTER(INDEX(test_output!K:FT,0,A29),[1]train_xl!$I:$I="sim"))} -> #DIV/0! | F29: {=AVERAGE(_xlfn._xlws.FILTER(INDEX(test_output!K:FT,0,A29),[1]train_xl!$Y:$Y="not neg pair"))} -> #VALUE! | G29: {=AVERAGE(_xlfn._xlws.FILTER(INDEX(test_output!K:FT,0,A29),[1]train_xl!$Z:$Z=1))} -> #VALUE! | H29: {=AVERAGE(_xlfn._xlws.FILTER(INDEX(test_output!K:FT,0,A29),[1]train_xl!$AA:$AA="neg"))} -> #VALUE! | I29: {=AVERAGE(_xlfn._xlws.FILTER(INDEX(test_output!K:FT,0,A29),[1]train_xl!$AA:$AA="intens"))} -> #VALUE!
A30: =A29+3 -> 87 | B30: {=LEFT(INDEX(test_output!K:FU,1,A30),LEN(INDEX(test_output!K:FU,1,A30))-4)} -> #VALUE! | C30: =AVERAGE(INDEX(test_output!K:FT,0,A30)) -> #DIV/0! | D30: {=AVERAGE(_xlfn._xlws.FILTER(INDEX(test_output!K:FT,0,A30),[1]train_xl!$I:$I="met"))} -> #DIV/0! | E30: {=AVERAGE(_xlfn._xlws.FILTER(INDEX(test_output!K:FT,0,A30),[1]train_xl!$I:$I="sim"))} -> #DIV/0! | F30: {=AVERAGE(_xlfn._xlws.FILTER(INDEX(test_output!K:FT,0,A30),[1]train_xl!$Y:$Y="not neg pair"))} -> #VALUE! | G30: {=AVERAGE(_xlfn._xlws.FILTER(INDEX(test_output!K:FT,0,A30),[1]train_xl!$Z:$Z=1))} -> #VALUE! | H30: {=AVERAGE(_xlfn._xlws.FILTER(INDEX(test_output!K:FT,0,A30),[1]train_xl!$AA:$AA="neg"))} -> #VALUE! | I30: {=AVERAGE(_xlfn._xlws.FILTER(INDEX(test_output!K:FT,0,A30),[1]train_xl!$AA:$AA="intens"))} -> #VALUE!
A31: =A30+3 -> 90 | B31: {=LEFT(INDEX(test_output!K:FU,1,A31),LEN(INDEX(test_output!K:FU,1,A31))-4)} -> #VALUE! | C31: =AVERAGE(INDEX(test_output!K:FT,0,A31)) -> #DIV/0! | D31: {=AVERAGE(_xlfn._xlws.FILTER(INDEX(test_output!K:FT,0,A31),[1]train_xl!$I:$I="met"))} -> #DIV/0! | E31: {=AVERAGE(_xlfn._xlws.FILTER(INDEX(test_output!K:FT,0,A31),[1]train_xl!$I:$I="sim"))} -> #DIV/0! | F31: {=AVERAGE(_xlfn._xlws.FILTER(INDEX(test_output!K:FT,0,A31),[1]train_xl!$Y:$Y="not neg pair"))} -> #VALUE! | G31: {=AVERAGE(_xlfn._xlws.FILTER(INDEX(test_output!K:FT,0,A31),[1]train_xl!$Z:$Z=1))} -> #VALUE! | H31: {=AVERAGE(_xlfn._xlws.FILTER(INDEX(test_output!K:FT,0,A31),[1]train_xl!$AA:$AA="neg"))} -> #VALUE! | I31: {=AVERAGE(_xlfn._xlws.FILTER(INDEX(test_output!K:FT,0,A31),[1]train_xl!$AA:$AA="intens"))} -> #VALUE!
A32: =A31+3 -> 93 | B32: {=LEFT(INDEX(test_output!K:FU,1,A32),LEN(INDEX(test_output!K:FU,1,A32))-4)} -> #VALUE! | C32: =AVERAGE(INDEX(test_output!K:FT,0,A32)) -> #DIV/0! | D32: {=AVERAGE(_xlfn._xlws.FILTER(INDEX(test_output!K:FT,0,A32),[1]train_xl!$I:$I="met"))} -> #DIV/0! | E32: {=AVERAGE(_xlfn._xlws.FILTER(INDEX(test_output!K:FT,0,A32),[1]train_xl!$I:$I="sim"))} -> #DIV/0! | F32: {=AVERAGE(_xlfn._xlws.FILTER(INDEX(test_output!K:FT,0,A32),[1]train_xl!$Y:$Y="not neg pair"))} -> #VALUE! | G32: {=AVERAGE(_xlfn._xlws.FILTER(INDEX(test_output!K:FT,0,A32),[1]train_xl!$Z:$Z=1))} -> #VALUE! | H32: {=AVERAGE(_xlfn._xlws.FILTER(INDEX(test_output!K:FT,0,A32),[1]train_xl!$AA:$AA="neg"))} -> #VALUE! | I32: {=AVERAGE(_xlfn._xlws.FILTER(INDEX(test_output!K:FT,0,A32),[1]train_xl!$AA:$AA="intens"))} -> #VALUE!
A33: =A32+3 -> 96 | B33: {=LEFT(INDEX(test_output!K:FU,1,A33),LEN(INDEX(test_output!K:FU,1,A33))-4)} -> #VALUE! | C33: =AVERAGE(INDEX(test_output!K:FT,0,A33)) -> #DIV/0! | D33: {=AVERAGE(_xlfn._xlws.FILTER(INDEX(test_output!K:FT,0,A33),[1]train_xl!$I:$I="met"))} -> #DIV/0! | E33: {=AVERAGE(_xlfn._xlws.FILTER(INDEX(test_output!K:FT,0,A33),[1]train_xl!$I:$I="sim"))} -> #DIV/0! | F33: {=AVERAGE(_xlfn._xlws.FILTER(INDEX(test_output!K:FT,0,A33),[1]train_xl!$Y:$Y="not neg pair"))} -> #VALUE! | G33: {=AVERAGE(_xlfn._xlws.FILTER(INDEX(test_output!K:FT,0,A33),[1]train_xl!$Z:$Z=1))} -> #VALUE! | H33: {=AVERAGE(_xlfn._xlws.FILTER(INDEX(test_output!K:FT,0,A33),[1]train_xl!$AA:$AA="neg"))} -> #VALUE! | I33: {=AVERAGE(_xlfn._xlws.FILTER(INDEX(test_output!K:FT,0,A33),[1]train_xl!$AA:$AA="intens"))} -> #VALUE!
... A56: =A55+3 -> 165 | B56: {=LEFT(INDEX(test_output!K:FU,1,A56),LEN(INDEX(test_output!K:FU,1,A56))-4)} -> #VALUE! | C56: =AVERAGE(INDEX(test_output!K:FT,0,A56)) -> #DIV/0! | D56: {=AVERAGE(_xlfn._xlws.FILTER(INDEX(test_output!K:FT,0,A56),[1]train_xl!$I:$I="met"))} -> #DIV/0! | E56: {=AVERAGE(_xlfn._xlws.FILTER(INDEX(test_output!K:FT,0,A56),[1]train_xl!$I:$I="sim"))} -> #DIV/0! | F56: {=AVERAGE(_xlfn._xlws.FILTER(INDEX(test_output!K:FT,0,A56),[1]train_xl!$Y:$Y="not neg pair"))} -> #VALUE! | G56: {=AVERAGE(_xlfn._xlws.FILTER(INDEX(test_output!K:FT,0,A56),[1]train_xl!$Z:$Z=1))} -> #VALUE! | H56: {=AVERAGE(_xlfn._xlws.FILTER(INDEX(test_output!K:FT,0,A56),[1]train_xl!$AA:$AA="neg"))} -> #VALUE! | I56: {=AVERAGE(_xlfn._xlws.FILTER(INDEX(test_output!K:FT,0,A56),[1]train_xl!$AA:$AA="intens"))} -> #VALUE!
A57: =A56+3 -> 168 | B57: {=RIGHT(INDEX(test_output!K:FU,1,A57),LEN(INDEX(test_output!K:FU,1,A57))-4)} -> #REF! | C57: =AVERAGE(INDEX(test_output!K:FT,0,A57)) -> #REF! | D57: {=AVERAGE(_xlfn._xlws.FILTER(INDEX(test_output!K:FT,0,A57),[3]train_xl!$I:$I="met"))} -> #REF! | E57: {=AVERAGE(_xlfn._xlws.FILTER(INDEX(test_output!K:FT,0,A57),[3]train_xl!$I:$I="sim"))} -> #REF! | F57: {=AVERAGE(_xlfn._xlws.FILTER(INDEX(test_output!K:FT,0,A57),[3]train_xl!$V:$V="not neg pair"))} -> #REF! | G57: {=AVERAGE(_xlfn._xlws.FILTER(INDEX(test_output!K:FT,0,A57),[3]train_xl!$W:$W=1))} -> #REF! | H57: {=AVERAGE(_xlfn._xlws.FILTER(INDEX(test_output!K:FT,0,A57),[3]train_xl!$X:$X="neg"))} -> #REF! | I57: {=AVERAGE(_xlfn._xlws.FILTER(INDEX(test_output!K:FT,0,A57),[3]train_xl!$X:$X="intens"))} -> #REF!
A58: =A57+3 -> 171 | B58: {=RIGHT(INDEX(test_output!K:FU,1,A58),LEN(INDEX(test_output!K:FU,1,A58))-4)} -> #REF! | C58: =AVERAGE(INDEX(test_output!K:FT,0,A58)) -> #REF! | D58: {=AVERAGE(_xlfn._xlws.FILTER(INDEX(test_output!K:FT,0,A58),[3]train_xl!$I:$I="met"))} -> #REF! | E58: {=AVERAGE(_xlfn._xlws.FILTER(INDEX(test_output!K:FT,0,A58),[3]train_xl!$I:$I="sim"))} -> #REF! | F58: {=AVERAGE(_xlfn._xlws.FILTER(INDEX(test_output!K:FT,0,A58),[3]train_xl!$V:$V="not neg pair"))} -> #REF! | G58: {=AVERAGE(_xlfn._xlws.FILTER(INDEX(test_output!K:FT,0,A58),[3]train_xl!$W:$W=1))} -> #REF! | H58: {=AVERAGE(_xlfn._xlws.FILTER(INDEX(test_output!K:FT,0,A58),[3]train_xl!$X:$X="neg"))} -> #REF! | I58: {=AVERAGE(_xlfn._xlws.FILTER(INDEX(test_output!K:FT,0,A58),[3]train_xl!$X:$X="intens"))} -> #REF!

Sheet counts for errors
B1: model | C1: all average | D1: all count total | E1: all count correct | F1: all lower interval | G1: all upper interval | H1: met average | I1: met count total | J1: met count correct | K1: met lower interval | L1: met upper interval | M1: sim average | N1: sim count total | O1: sim count correct | P1: sim lower interval | Q1: sim upper interval | R1: not neg pairs average | S1: not neg pairs count total | T1: not neg pairs count correct | U1: not neg pairs lower interval | V1: not neg pairs upper interval | W1: neg pairs average | X1: neg pairs count total | Y1: neg pairs count correct | Z1: neg pairs lower interval | AA1: neg pairs upper interval | AB1: neg average | AC1: neg count total | AD1: neg count correct | AE1: neg lower interval | AF1: neg upper interval | AG1: intens average | AH1: intens count total | AI1: intens count correct | AJ1: intens lower interval | AK1: intens upper interval | AL1: neg not average | AM1: neg not count total | AN1: neg not count correct | AO1: neg not lower interval | AP1: neg not upper interval | AQ1: intens not average | AR1: intens not count total | AS1: intens not count correct | AT1: intens not lower interval | AU1: intens not upper interval | AV1: neg antonym average | AW1: neg antonym count total | AX1: neg antonym count correct | AY1: neg antonym lower interval | AZ1: neg antonym upper interval | BA1: intens antonym average | BB1: intens antonym count total | BC1: intens antonym count correct | BD1: intens antonym lower interval | BE1: intens antonym upper interval | BF1: past tense average | BG1: past tense count total | BH1: past tense count correct | BI1: past tense lower interval | BJ1: past tense upper interval | BK1: present tense average | BL1: present tense count total | BM1: present tense count correct | BN1: present tense lower interval | BO1: present tense upper interval | BP1: low concreteness average | BQ1: low concreteness count total | BR1: low concreteness count correct | BS1: low concreteness lower interval | BT1: low concreteness upper interval | BU1: high concreteness average | BV1: high concreteness count total | BW1: high concreteness count correct | BX1: high concreteness lower interval | BY1: high concreteness upper interval | BZ1: litneg originals average | CA1: litneg originals count total | CB1: litneg originals count correct | CC1: litneg originals lower interval | CD1: litneg originals upper interval | CE1: litneg originals intens average | CF1: litneg originals intens count total | CG1: litneg originals intens count correct | CH1: litneg originals intens lower interval | CI1: litneg originals intens upper interval | CJ1: litneg originals neg average | CK1: litneg originals neg count total | CL1: litneg originals neg count correct | CM1: litneg originals neg lower interval | CN1: litneg originals neg upper interval
A2: 3 | B2: {=INDEX(test_output!K:FQ,1,A2)} -> Llama-3-70B-Instruct M1 bin | C2: =AVERAGE(INDEX(test_output!K:FP,0,A2)) -> 0.79296875 | D2: =COUNT(INDEX(test_output!K:FP,0,A2)) -> 256 | E2: {=COUNT(_xlfn._xlws.FILTER(INDEX(test_output!K:FP,0,A2),INDEX(test_output!K:FP,0,A2)=1))} -> 203 | H2: {=AVERAGE(_xlfn._xlws.FILTER(INDEX(test_output!K:FP,0,A2),[1]train_xl!$I:$I="met"))} -> 0.80851064 | I2: {=COUNT(_xlfn._xlws.FILTER(INDEX(test_output!K:FP,0,A2),[1]train_xl!$I:$I="met"))} -> 47 | J2: {=COUNT(_xlfn._xlws.FILTER(INDEX(test_output!K:FP,0,A2),([1]train_xl!$I:$I="met")*(INDEX(test_output!K:FP,0,A2)=1)))} -> 38 | M2: {=AVERAGE(_xlfn._xlws.FILTER(INDEX(test_output!K:FP,0,A2),[1]train_xl!$I:$I="sim"))} -> 0.78947368 | N2: {=COUNT(_xlfn._xlws.FILTER(INDEX(test_output!K:FP,0,A2),[1]train_xl!$I:$I="sim"))} -> 209 | O2: {=COUNT(_xlfn._xlws.FILTER(INDEX(test_output!K:FP,0,A2),([1]train_xl!$I:$I="sim")*(INDEX(test_output!K:FP,0,A2)=1)))} -> 165 | R2: {=AVERAGE(_xlfn._xlws.FILTER(INDEX(test_output!K:FP,0,A2),[1]train_xl!$Y:$Y="not neg pair"))} -> #VALUE! | S2: {=COUNT(_xlfn._xlws.FILTER(INDEX(test_output!K:FP,0,A2),[1]train_xl!$Y:$Y="not neg pair"))} -> 0 | T2: {=COUNT(_xlfn._xlws.FILTER(INDEX(test_output!K:FP,0,A2),([1]train_xl!$Y:$Y="not neg pair")*(INDEX(test_output!K:FP,0,A2)=1)))} -> 0 | W2: {=AVERAGE(_xlfn._xlws.FILTER(INDEX(test_output!K:FP,0,A2),OR([1]train_xl!$Y:$Y="not",[1]train_xl!$Y:$Y="antonym")))} -> #VALUE! | X2: {=COUNT(_xlfn._xlws.FILTER(INDEX(test_output!K:FP,0,A2),([1]train_xl!$Y:$Y="not")+([1]train_xl!$Y:$Y="antonym")))} -> 0 | Y2: {=COUNT(_xlfn._xlws.FILTER(INDEX(test_output!K:FP,0,A2),(INDEX(test_output!K:FP,0,A2)=1)*(([1]train_xl!$Y:$Y="not")+([1]train_xl!$Y:$Y="antonym"))))} -> 0 | AB2: {=AVERAGE(_xlfn._xlws.FILTER(INDEX(test_output!K:FP,0,A2),[1]train_xl!$AA:$AA="neg"))} -> #VALUE! | AC2: {=COUNT(_xlfn._xlws.FILTER(INDEX(test_output!K:FP,0,A2),[1]train_xl!$AA:$AA="neg"))} -> 0 | AD2: {=COUNT(_xlfn._xlws.FILTER(INDEX(test_output!K:FP,0,A2),([1]train_xl!$AA:$AA="neg")*(INDEX(test_output!K:FP,0,A2)=1)))} -> 0 | AG2: {=AVERAGE(_xlfn._xlws.FILTER(INDEX(test_output!K:FP,0,A2),[1]train_xl!$AA:$AA="intens"))} -> #VALUE! | AH2: {=COUNT(_xlfn._xlws.FILTER(INDEX(test_output!K:FP,0,A2),[1]train_xl!$AA:$AA="intens"))} -> 0 | AI2: {=COUNT(_xlfn._xlws.FILTER(INDEX(test_output!K:FP,0,A2),([1]train_xl!$AA:$AA="intens")*(INDEX(test_output!K:FP,0,A2)=1)))} -> 0 | AL2: {=AVERAGE(_xlfn._xlws.FILTER(INDEX(test_output!K:FP,0,A2),([1]train_xl!$Y:$Y="not")*([1]train_xl!$AA:$AA="neg")))} -> #VALUE! | AM2: {=COUNT(_xlfn._xlws.FILTER(INDEX(test_output!K:FP,0,A2),([1]train_xl!$Y:$Y="not")*([1]train_xl!$AA:$AA="neg")))} -> 0 | AN2: {=COUNT(_xlfn._xlws.FILTER(INDEX(test_output!K:FP,0,A2),([1]train_xl!$Y:$Y="not")*([1]train_xl!$AA:$AA="neg")*(INDEX(test_output!K:FP,0,A2)=1)))} -> 0 | AQ2: {=AVERAGE(_xlfn._xlws.FILTER(INDEX(test_output!K:FP,0,A2),([1]train_xl!$Y:$Y="not")*([1]train_xl!$AA:$AA="intens")))} -> #VALUE! | AR2: {=COUNT(_xlfn._xlws.FILTER(INDEX(test_output!K:FP,0,A2),([1]train_xl!$Y:$Y="not")*([1]train_xl!$AA:$AA="intens")))} -> 0 | AS2: {=COUNT(_xlfn._xlws.FILTER(INDEX(test_output!K:FP,0,A2),([1]train_xl!$Y:$Y="not")*([1]train_xl!$AA:$AA="intens")*(INDEX(test_output!K:FP,0,A2)=1)))} -> 0 | AV2: {=AVERAGE(_xlfn._xlws.FILTER(INDEX(test_output!K:FP,0,A2),([1]train_xl!$Y:$Y="antonym")*([1]train_xl!$AA:$AA="neg")))} -> #VALUE! | AW2: {=COUNT(_xlfn._xlws.FILTER(INDEX(test_output!K:FP,0,A2),([1]train_xl!$Y:$Y="antonym")*([1]train_xl!$AA:$AA="neg")))} -> 0 | AX2: {=COUNT(_xlfn._xlws.FILTER(INDEX(test_output!K:FP,0,A2),([1]train_xl!$Y:$Y="antonym")*([1]train_xl!$AA:$AA="neg")*(INDEX(test_output!K:FP,0,A2)=1)))} -> 0 | BA2: {=AVERAGE(_xlfn._xlws.FILTER(INDEX(test_output!K:FP,0,A2),([1]train_xl!$Y:$Y="antonym")*([1]train_xl!$AA:$AA="intens")))} -> #VALUE! | BB2: {=COUNT(_xlfn._xlws.FILTER(INDEX(test_output!K:FP,0,A2),([1]train_xl!$Y:$Y="antonym")*([1]train_xl!$AA:$AA="intens")))} -> 0 | BC2: {=COUNT(_xlfn._xlws.FILTER(INDEX(test_output!K:FP,0,A2),([1]train_xl!$Y:$Y="antonym")*([1]train_xl!$AA:$AA="intens")*(INDEX(test_output!K:FP,0,A2)=1)))} -> 0 | BF2: {=AVERAGE(_xlfn._xlws.FILTER(INDEX(test_output!K:FP,0,A2),[1]train_xl!$AB:$AB="Past"))} -> #VALUE! | BG2: {=COUNT(_xlfn._xlws.FILTER(INDEX(test_output!K:FP,0,A2),[1]train_xl!$AB:$AB="Past"))} -> 0 | BH2: {=COUNT(_xlfn._xlws.FILTER(INDEX(test_output!K:FP,0,A2),([1]train_xl!$AB:$AB="Past")*(INDEX(test_output!K:FP,0,A2)=1)))} -> 0 | BK2: {=AVERAGE(_xlfn._xlws.FILTER(INDEX(test_output!K:FP,0,A2),[1]train_xl!$AB:$AB="Pres"))} -> #VALUE! | BL2: {=COUNT(_xlfn._xlws.FILTER(INDEX(test_output!K:FP,0,A2),[1]train_xl!$AB:$AB="Pres"))} -> 0 | BM2: {=COUNT(_xlfn._xlws.FILTER(INDEX(test_output!K:FP,0,A2),([1]train_xl!$AB:$AB="Pres")*(INDEX(test_output!K:FP,0,A2)=1)))} -> 0 | BP2: {=AVERAGE(_xlfn._xlws.FILTER(INDEX(test_output!K:FP,0,A2),[1]train_xl!$AD:$AD="L"))} -> #VALUE! | BQ2: {=COUNT(_xlfn._xlws.FILTER(INDEX(test_output!K:FP,0,A2),[1]train_xl!$AD:$AD="L"))} -> 0 | BR2: {=COUNT(_xlfn._xlws.FILTER(INDEX(test_output!K:FP,0,A2),([1]train_xl!$AD:$AD="L")*(INDEX(test_output!K:FP,0,A2)=1)))} -> 0 | BU2: {=AVERAGE(_xlfn._xlws.FILTER(INDEX(test_output!K:FP,0,A2),[1]train_xl!$AD:$AD="H"))} -> #VALUE! | BV2: {=COUNT(_xlfn._xlws.FILTER(INDEX(test_output!K:FP,0,A2),[1]train_xl!$AD:$AD="H"))} -> 0 | BW2: {=COUNT(_xlfn._xlws.FILTER(INDEX(test_output!K:FP,0,A2),([1]train_xl!$AD:$AD="H")*(INDEX(test_output!K:FP,0,A2)=1)))} -> 0 | BZ2: {=AVERAGE(_xlfn._xlws.FILTER(INDEX(test_output!K:FP,0,A2),[1]train_xl!$AE:$AE=1))} -> #VALUE! | CA2: {=COUNT(_xlfn._xlws.FILTER(INDEX(test_output!K:FP,0,A2),[1]train_xl!$AE:$AE=1))} -> 0 | CB2: {=COUNT(_xlfn._xlws.FILTER(INDEX(test_output!K:FP,0,A2),([1]train_xl!$AE:$AE=1)*(INDEX(test_output!K:FP,0,A2)=1)))} -> 0 | CE2: {=AVERAGE(_xlfn._xlws.FILTER(INDEX(test_output!K:FP,0,A2),([1]train_xl!$AE:$AE=1)*([1]train_xl!$AA:$AA="intens")))} -> #VALUE! | CF2: {=COUNT(_xlfn._xlws.FILTER(INDEX(test_output!K:FP,0,A2),([1]train_xl!$AE:$AE=1)*([1]train_xl!$AA:$AA="intens")))} -> 0 | CG2: {=COUNT(_xlfn._xlws.FILTER(INDEX(test_output!K:FP,0,A2),([1]train_xl!$AE:$AE=1)*([1]train_xl!$AA:$AA="intens")*(INDEX(test_output!K:FP,0,A2)=1)))} -> 0 | CJ2: {=AVERAGE(_xlfn._xlws.FILTER(INDEX(test_output!K:FP,0,A2),([1]train_xl!$AE:$AE=1)*([1]train_xl!$AA:$AA="neg")))} -> #VALUE! | CK2: {=COUNT(_xlfn._xlws.FILTER(INDEX(test_output!K:FP,0,A2),([1]train_xl!$AE:$AE=1)*([1]train_xl!$AA:$AA="neg")))} -> 0 | CL2: {=COUNT(_xlfn._xlws.FILTER(INDEX(test_output!K:FP,0,A2),([1]train_xl!$AE:$AE=1)*([1]train_xl!$AA:$AA="neg")*(INDEX(test_output!K:FP,0,A2)=1)))} -> 0
A3: =A2+3 -> 6 | B3: {=INDEX(test_output!K:FQ,1,A3)} -> Llama-3-70B-Instruct M2 bin | C3: =AVERAGE(INDEX(test_output!K:FP,0,A3)) -> 0.82421875 | D3: =COUNT(INDEX(test_output!K:FP,0,A3)) -> 256 | E3: {=COUNT(_xlfn._xlws.FILTER(INDEX(test_output!K:FP,0,A3),INDEX(test_output!K:FP,0,A3)=1))} -> 211 | H3: {=AVERAGE(_xlfn._xlws.FILTER(INDEX(test_output!K:FP,0,A3),[1]train_xl!$I:$I="met"))} -> 0.87234043 | I3: {=COUNT(_xlfn._xlws.FILTER(INDEX(test_output!K:FP,0,A3),[1]train_xl!$I:$I="met"))} -> 47 | J3: {=COUNT(_xlfn._xlws.FILTER(INDEX(test_output!K:FP,0,A3),([1]train_xl!$I:$I="met")*(INDEX(test_output!K:FP,0,A3)=1)))} -> 41 | M3: {=AVERAGE(_xlfn._xlws.FILTER(INDEX(test_output!K:FP,0,A3),[1]train_xl!$I:$I="sim"))} -> 0.81339713 | N3: {=COUNT(_xlfn._xlws.FILTER(INDEX(test_output!K:FP,0,A3),[1]train_xl!$I:$I="sim"))} -> 209 | O3: {=COUNT(_xlfn._xlws.FILTER(INDEX(test_output!K:FP,0,A3),([1]train_xl!$I:$I="sim")*(INDEX(test_output!K:FP,0,A3)=1)))} -> 170 | AB3: {=AVERAGE(_xlfn._xlws.FILTER(INDEX(test_output!K:FP,0,A3),[1]train_xl!$AA:$AA="neg"))} -> #VALUE! | AC3: {=COUNT(_xlfn._xlws.FILTER(INDEX(test_output!K:FP,0,A3),[1]train_xl!$AA:$AA="neg"))} -> 0 | AD3: {=COUNT(_xlfn._xlws.FILTER(INDEX(test_output!K:FP,0,A3),([1]train_xl!$AA:$AA="neg")*(INDEX(test_output!K:FP,0,A3)=1)))} -> 0 | AG3: {=AVERAGE(_xlfn._xlws.FILTER(INDEX(test_output!K:FP,0,A3),[1]train_xl!$AA:$AA="intens"))} -> #VALUE! | AH3: {=COUNT(_xlfn._xlws.FILTER(INDEX(test_output!K:FP,0,A3),[1]train_xl!$AA:$AA="intens"))} -> 0 | AI3: {=COUNT(_xlfn._xlws.FILTER(INDEX(test_output!K:FP,0,A3),([1]train_xl!$AA:$AA="intens")*(INDEX(test_output!K:FP,0,A3)=1)))} -> 0 | AL3: {=AVERAGE(_xlfn._xlws.FILTER(INDEX(test_output!K:FP,0,A3),([1]train_xl!$Y:$Y="not")*([1]train_xl!$AA:$AA="neg")))} -> #VALUE! | AM3: {=COUNT(_xlfn._xlws.FILTER(INDEX(test_output!K:FP,0,A3),([1]train_xl!$Y:$Y="not")*([1]train_xl!$AA:$AA="neg")))} -> 0 | AN3: {=COUNT(_xlfn._xlws.FILTER(INDEX(test_output!K:FP,0,A3),([1]train_xl!$Y:$Y="not")*([1]train_xl!$AA:$AA="neg")*(INDEX(test_output!K:FP,0,A3)=1)))} -> 0 | AQ3: {=AVERAGE(_xlfn._xlws.FILTER(INDEX(test_output!K:FP,0,A3),([1]train_xl!$Y:$Y="not")*([1]train_xl!$AA:$AA="intens")))} -> #VALUE! | AR3: {=COUNT(_xlfn._xlws.FILTER(INDEX(test_output!K:FP,0,A3),([1]train_xl!$Y:$Y="not")*([1]train_xl!$AA:$AA="intens")))} -> 0 | AS3: {=COUNT(_xlfn._xlws.FILTER(INDEX(test_output!K:FP,0,A3),([1]train_xl!$Y:$Y="not")*([1]train_xl!$AA:$AA="intens")*(INDEX(test_output!K:FP,0,A3)=1)))} -> 0 | AV3: {=AVERAGE(_xlfn._xlws.FILTER(INDEX(test_output!K:FP,0,A3),([1]train_xl!$Y:$Y="antonym")*([1]train_xl!$AA:$AA="neg")))} -> #VALUE! | AW3: {=COUNT(_xlfn._xlws.FILTER(INDEX(test_output!K:FP,0,A3),([1]train_xl!$Y:$Y="antonym")*([1]train_xl!$AA:$AA="neg")))} -> 0 | AX3: {=COUNT(_xlfn._xlws.FILTER(INDEX(test_output!K:FP,0,A3),([1]train_xl!$Y:$Y="antonym")*([1]train_xl!$AA:$AA="neg")*(INDEX(test_output!K:FP,0,A3)=1)))} -> 0 | BA3: {=AVERAGE(_xlfn._xlws.FILTER(INDEX(test_output!K:FP,0,A3),([1]train_xl!$Y:$Y="antonym")*([1]train_xl!$AA:$AA="intens")))} -> #VALUE! | BB3: {=COUNT(_xlfn._xlws.FILTER(INDEX(test_output!K:FP,0,A3),([1]train_xl!$Y:$Y="antonym")*([1]train_xl!$AA:$AA="intens")))} -> 0 | BC3: {=COUNT(_xlfn._xlws.FILTER(INDEX(test_output!K:FP,0,A3),([1]train_xl!$Y:$Y="antonym")*([1]train_xl!$AA:$AA="intens")*(INDEX(test_output!K:FP,0,A3)=1)))} -> 0 | BF3: {=AVERAGE(_xlfn._xlws.FILTER(INDEX(test_output!K:FP,0,A3),[1]train_xl!$AB:$AB="Past"))} -> #VALUE! | BG3: {=COUNT(_xlfn._xlws.FILTER(INDEX(test_output!K:FP,0,A3),[1]train_xl!$AB:$AB="Past"))} -> 0 | BH3: {=COUNT(_xlfn._xlws.FILTER(INDEX(test_output!K:FP,0,A3),([1]train_xl!$AB:$AB="Past")*(INDEX(test_output!K:FP,0,A3)=1)))} -> 0 | BK3: {=AVERAGE(_xlfn._xlws.FILTER(INDEX(test_output!K:FP,0,A3),[1]train_xl!$AB:$AB="Pres"))} -> #VALUE! | BL3: {=COUNT(_xlfn._xlws.FILTER(INDEX(test_output!K:FP,0,A3),[1]train_xl!$AB:$AB="Pres"))} -> 0 | BM3: {=COUNT(_xlfn._xlws.FILTER(INDEX(test_output!K:FP,0,A3),([1]train_xl!$AB:$AB="Pres")*(INDEX(test_output!K:FP,0,A3)=1)))} -> 0 | BP3: {=AVERAGE(_xlfn._xlws.FILTER(INDEX(test_output!K:FP,0,A3),[1]train_xl!$AD:$AD="L"))} -> #VALUE! | BQ3: {=COUNT(_xlfn._xlws.FILTER(INDEX(test_output!K:FP,0,A3),[1]train_xl!$AD:$AD="L"))} -> 0 | BR3: {=COUNT(_xlfn._xlws.FILTER(INDEX(test_output!K:FP,0,A3),([1]train_xl!$AD:$AD="L")*(INDEX(test_output!K:FP,0,A3)=1)))} -> 0 | BU3: {=AVERAGE(_xlfn._xlws.FILTER(INDEX(test_output!K:FP,0,A3),[1]train_xl!$AD:$AD="H"))} -> #VALUE! | BV3: {=COUNT(_xlfn._xlws.FILTER(INDEX(test_output!K:FP,0,A3),[1]train_xl!$AD:$AD="H"))} -> 0 | BW3: {=COUNT(_xlfn._xlws.FILTER(INDEX(test_output!K:FP,0,A3),([1]train_xl!$AD:$AD="H")*(INDEX(test_output!K:FP,0,A3)=1)))} -> 0 | BZ3: {=AVERAGE(_xlfn._xlws.FILTER(INDEX(test_output!K:FP,0,A3),[1]train_xl!$AE:$AE=1))} -> #VALUE! | CA3: {=COUNT(_xlfn._xlws.FILTER(INDEX(test_output!K:FP,0,A3),[1]train_xl!$AE:$AE=1))} -> 0 | CB3: {=COUNT(_xlfn._xlws.FILTER(INDEX(test_output!K:FP,0,A3),([1]train_xl!$AE:$AE=1)*(INDEX(test_output!K:FP,0,A3)=1)))} -> 0 | CE3: {=AVERAGE(_xlfn._xlws.FILTER(INDEX(test_output!K:FP,0,A3),([1]train_xl!$AE:$AE=1)*([1]train_xl!$AA:$AA="intens")))} -> #VALUE! | CF3: {=COUNT(_xlfn._xlws.FILTER(INDEX(test_output!K:FP,0,A3),([1]train_xl!$AE:$AE=1)*([1]train_xl!$AA:$AA="intens")))} -> 0 | CG3: {=COUNT(_xlfn._xlws.FILTER(INDEX(test_output!K:FP,0,A3),([1]train_xl!$AE:$AE=1)*([1]train_xl!$AA:$AA="intens")*(INDEX(test_output!K:FP,0,A3)=1)))} -> 0 | CJ3: {=AVERAGE(_xlfn._xlws.FILTER(INDEX(test_output!K:FP,0,A3),([1]train_xl!$AE:$AE=1)*([1]train_xl!$AA:$AA="neg")))} -> #VALUE! | CK3: {=COUNT(_xlfn._xlws.FILTER(INDEX(test_output!K:FP,0,A3),([1]train_xl!$AE:$AE=1)*([1]train_xl!$AA:$AA="neg")))} -> 0 | CL3: {=COUNT(_xlfn._xlws.FILTER(INDEX(test_output!K:FP,0,A3),([1]train_xl!$AE:$AE=1)*([1]train_xl!$AA:$AA="neg")*(INDEX(test_output!K:FP,0,A3)=1)))} -> 0
